<?xml version='1.0' encoding='utf-8'?>
<robot xmlns:xacro="http://www.ros.org/wiki/xacro" name="openarm">

  <xacro:include filename="$(find openarm_description)/urdf/arm/openarm_macro.xacro" />

  <!-- arm_type: Namespace of the robot arm. Serves to differentiate between arms in case of multiple instances. -->
  <!-- joint_limits: description of the joint limits that comes from a YAML file. Example definition: ${xacro.load_yaml('$(find openarm_description)/robots/fr3/joint_limits.yaml')} -->
  <!-- kinematics: description of the kinematics that comes from a YAML file. Example definition: ${xacro.load_yaml('$(find openarm_description)/robots/fr3/kinematics.yaml')} -->
  <!-- inertials: description of the inertials that comes from a YAML file. Example definition: ${xacro.load_yaml('$(find openarm_description)/robots/fr3/inertials.yaml')} -->

  <xacro:macro name="openarm_arm" params="arm_type arm_prefix:='' no_prefix:=false description_pkg:='openarm_description' connected_to:='base' xyz:='0 0 0' rpy:='0 0 0' gazebo:='false' joint_limits inertials kinematics kinematics_link kinematics_offset:=none " >

    <!-- Define a property that defaults to 'arm_prefix_arm_type' concatenated with an underscore if 'no_prefix' is not set -->
     
    <!-- <xacro:property name="prefix" value="${'' if no_prefix else arm_prefix + arm_type + '_'}" /> -->
    <xacro:property name="prefix" value="${'' if no_prefix else arm_prefix + 'openarm' + '_'}" />

    <xacro:if value="${arm_prefix == 'right_'}">
      <xacro:property name="reflect" value="1" />
    </xacro:if>

    <xacro:unless value="${arm_prefix == 'right_'}">
      <xacro:property name="reflect" value="-1" />
    </xacro:unless>

    <xacro:if value="${gazebo}">
      <xacro:property name="connected_to" value="" />
    </xacro:if>

    <xacro:unless value="${connected_to == ''}">
      <!-- <link name="${connected_to}">
      </link> -->
      <joint name="${prefix}${connected_to}_joint" type="fixed">
        <parent link="${connected_to}"/>
        <child link="${prefix}link0"/>
        <origin rpy="${rpy}" xyz="${xyz}"/>
      </joint>
    </xacro:unless>

    <xacro:link_with_sc no_prefix="${no_prefix}" name="link0" gazebo="${gazebo}" kinematics_link="${kinematics_link}" reflect="${reflect}"/>

    <xacro:link_with_sc no_prefix="${no_prefix}" name="link1" gazebo="${gazebo}" kinematics_link="${kinematics_link}" reflect="${reflect}"/>

    <joint name="${prefix}joint1" type="revolute">
      <xacro:openarm-kinematics name="joint1" config="${kinematics}" reflect="${reflect}"/>
      <parent link="${prefix}link0" />
      <child link="${prefix}link1" />
      <axis xyz="0 0 1" />
      <xacro:openarm-limits name="joint1" config="${joint_limits}" />
    </joint>

    <!-- for bimanual offset -->
    <xacro:link_with_sc no_prefix="${no_prefix}" name="link2" gazebo="${gazebo}" kinematics_link="${kinematics_link}" reflect="${reflect}"/>

    <xacro:property name="limit_offset_joint2" value="0" />

    <xacro:if value="${prefix.find('right_') != -1}">
      <xacro:property name="limit_offset_joint2" value="${pi/2}" />
    </xacro:if>
    
    <xacro:if value="${prefix.find('left_') != -1}">
      <xacro:property name="limit_offset_joint2" value="${-pi/2}" />
    </xacro:if>

    <joint name="${prefix}joint2" type="revolute">
      <xacro:openarm-kinematics name="joint2" config="${kinematics}" offset="${kinematics_offset}" reflect="${reflect}"/>
      <parent link="${prefix}link1" />
      <child link="${prefix}link2" />
      <axis xyz="-1 0 0" />
      <xacro:openarm-limits name="joint2" config="${joint_limits}" reflect="${reflect}" offset="${limit_offset_joint2}"/>
    </joint>
    
    <xacro:link_with_sc no_prefix="${no_prefix}" name="link3" gazebo="${gazebo}" kinematics_link="${kinematics_link}" reflect="${reflect}"/>

    <joint name="${prefix}joint3" type="revolute">
      <xacro:openarm-kinematics name="joint3" config="${kinematics}" />
      <parent link="${prefix}link2" />
      <child link="${prefix}link3" />
      <axis xyz="0 0 1" />
      <xacro:openarm-limits name="joint3" config="${joint_limits}" />
    </joint>

    <xacro:link_with_sc no_prefix="${no_prefix}" name="link4" gazebo="${gazebo}" kinematics_link="${kinematics_link}" />

    <joint name="${prefix}joint4" type="revolute">
      <xacro:openarm-kinematics name="joint4" config="${kinematics}" />
      <parent link="${prefix}link3" />
      <child link="${prefix}link4" />
      <axis xyz="0 1 0" />
      <xacro:openarm-limits name="joint4" config="${joint_limits}" />
    </joint>

    <xacro:link_with_sc no_prefix="${no_prefix}" name="link5" gazebo="${gazebo}" kinematics_link="${kinematics_link}" reflect="${reflect}" />

    <joint name="${prefix}joint5" type="revolute">
      <xacro:openarm-kinematics name="joint5" config="${kinematics}" />
      <parent link="${prefix}link4" />
      <child link="${prefix}link5" />
      <axis xyz="0 0 1" />
      <xacro:openarm-limits name="joint5" config="${joint_limits}" />
    </joint>

    <xacro:link_with_sc no_prefix="${no_prefix}" name="link6" gazebo="${gazebo}" kinematics_link="${kinematics_link}" reflect="${reflect}"/>

    <joint name="${prefix}joint6" type="revolute">
      <xacro:openarm-kinematics name="joint6" config="${kinematics}" />
      <parent link="${prefix}link5" />
      <child link="${prefix}link6" />
      <axis xyz="1 0 0" />
      <xacro:openarm-limits name="joint6" config="${joint_limits}" />
    </joint>

    <xacro:link_with_sc no_prefix="${no_prefix}" name="link7" gazebo="${gazebo}" rpy="0 0 0"  kinematics_link="${kinematics_link}" reflect="${reflect}"/>

    <joint name="${prefix}joint7" type="revolute">
      <xacro:openarm-kinematics name="joint7" config="${kinematics}" />
      <parent link="${prefix}link6"/>
      <child link="${prefix}link7"/>
      <axis xyz="0 1 0"/>
      <xacro:openarm-limits name="joint7" config="${joint_limits}" />
    </joint>

    <link name="${prefix}link8"/>

    <joint name="${prefix}joint8" type="fixed">
      <xacro:openarm-kinematics name="joint8" config="${kinematics}" />
      <parent link="${prefix}link7" />
      <child link="${prefix}link8" />
    </joint>

  </xacro:macro>
</robot>
