<?xml version="1.0" ?>
<!-- =================================================================================== -->
<!-- |    This document was autogenerated by xacro from openarm_v1_bimanual.urdf.xacro | -->
<!-- |    EDITING THIS FILE BY HAND IS NOT RECOMMENDED                                 | -->
<!-- =================================================================================== -->
<!--
　Copyright 2025 Reazon Holdings, Inc.

　Licensed under the Apache License, Version 2.0 (the "License");
　you may not use this file except in compliance with the License.
　You may obtain a copy of the License at

　    http://www.apache.org/licenses/LICENSE-2.0

　Unless required by applicable law or agreed to in writing, software
　distributed under the License is distributed on an "AS IS" BASIS,
　WITHOUT WARRANTIES OR CONDITIONS OF ANY KIND, either express or implied.
　See the License for the specific language governing permissions and
　limitations under the License.
-->
<robot name="openarm_v1_bimanual">
  <!-- <xacro:include filename="$(find openarm_v1_description)/urdf/materials.xacro" /> -->
  <!-- <xacro:include filename="$(find openarm_v1_description)/urdf/openarm_v1.trans" />
<xacro:include filename="$(find openarm_v1_description)/urdf/openarm_v1.gazebo" />
 -->
  <material name="silver">
    <color rgba="0.700 0.700 0.700 1.000"/>
  </material>
  <material name="dark_gray">
    <color rgba="0.2 0.2 0.2 1.0"/>
  </material>
  <link name="pedestal_v1_link">
    <visual>
      <origin rpy="0 0 0" xyz="0 0 0"/>
      <geometry>
        <mesh filename="package://openarm_v1_bimanual_description/meshes/pedestal_v1_link.stl" scale="0.001 0.001 0.001"/>
      </geometry>
      <material name="dark_gray"/>
    </visual>
    <collision>
      <origin rpy="0 0 0" xyz="0 0 0"/>
      <geometry>
        <mesh filename="package://openarm_v1_bimanual_description/meshes/pedestal_v1_link.stl" scale="0.001 0.001 0.001"/>
      </geometry>
    </collision>
    <!-- <inertial>
      <origin rpy="0 0 0" xyz="-0.019032202985360066 0.0002140713683395199 0.3878296171161416"/>
      <mass value="13.892221893766356"/>
      <inertia ixx="1.653382" ixy="5e-06" ixz="-0.085852" iyy="1.653298" iyz="0.000118" izz="0.051334"/>
    </inertial> -->
  </link>
  <material name="aluminum">
    <color rgba="0.5 0.5 0.5 1"/>
  </material>
  <material name="plastic">
    <color rgba="0.1 0.1 0.1 1"/>
  </material>
  <!-- camera body, with origin at bottom screw mount -->
  <joint name="camera_joint" type="fixed">
    <origin rpy="0.0 1.3962634015954636 -1.5707963267948966" xyz="0.0 -0.025 0.995216"/>
    <parent link="pedestal_v1_link"/>
    <child link="camera_bottom_screw_frame"/>
  </joint>
  <link name="camera_bottom_screw_frame"/>
  <joint name="camera_link_joint" type="fixed">
    <origin rpy="0 0 0" xyz="0.010600000000000002 0.0175 0.0125"/>
    <parent link="camera_bottom_screw_frame"/>
    <child link="camera_link"/>
  </joint>
  <link name="camera_link">
    <visual>
      <!-- the mesh origin is at front plate in between the two infrared camera axes -->
      <origin rpy="1.5707963267948966 0 1.5707963267948966" xyz="0.0043 -0.0175 0"/>
      <geometry>
        <mesh filename="package://realsense2_description/meshes/d435.dae"/>
      </geometry>
    </visual>
    <collision>
      <origin rpy="0 0 0" xyz="0 -0.0175 0"/>
      <geometry>
        <box size="0.02505 0.09 0.025"/>
      </geometry>
    </collision>
    <inertial>
      <!-- The following are not reliable values, and should not be used for modeling -->
      <mass value="0.072"/>
      <origin xyz="0 0 0"/>
      <inertia ixx="0.003881243" ixy="0.0" ixz="0.0" iyy="0.000498940" iyz="0.0" izz="0.003879257"/>
    </inertial>
  </link>
  <!-- camera depth joints and links -->
  <joint name="camera_depth_joint" type="fixed">
    <origin rpy="0 0 0" xyz="0 0 0"/>
    <parent link="camera_link"/>
    <child link="camera_depth_frame"/>
  </joint>
  <link name="camera_depth_frame"/>
  <joint name="camera_depth_optical_joint" type="fixed">
    <origin rpy="-1.5707963267948966 0 -1.5707963267948966" xyz="0 0 0"/>
    <parent link="camera_depth_frame"/>
    <child link="camera_depth_optical_frame"/>
  </joint>
  <link name="camera_depth_optical_frame"/>
  <!-- camera left IR joints and links -->
  <joint name="camera_infra1_joint" type="fixed">
    <origin rpy="0 0 0" xyz="0 0.0 0"/>
    <parent link="camera_link"/>
    <child link="camera_infra1_frame"/>
  </joint>
  <link name="camera_infra1_frame"/>
  <joint name="camera_infra1_optical_joint" type="fixed">
    <origin rpy="-1.5707963267948966 0 -1.5707963267948966" xyz="0 0 0"/>
    <parent link="camera_infra1_frame"/>
    <child link="camera_infra1_optical_frame"/>
  </joint>
  <link name="camera_infra1_optical_frame"/>
  <!-- camera right IR joints and links -->
  <joint name="camera_infra2_joint" type="fixed">
    <origin rpy="0 0 0" xyz="0 -0.05 0"/>
    <parent link="camera_link"/>
    <child link="camera_infra2_frame"/>
  </joint>
  <link name="camera_infra2_frame"/>
  <joint name="camera_infra2_optical_joint" type="fixed">
    <origin rpy="-1.5707963267948966 0 -1.5707963267948966" xyz="0 0 0"/>
    <parent link="camera_infra2_frame"/>
    <child link="camera_infra2_optical_frame"/>
  </joint>
  <link name="camera_infra2_optical_frame"/>
  <!-- camera color joints and links -->
  <joint name="camera_color_joint" type="fixed">
    <origin rpy="0 0 0" xyz="0 0.015 0"/>
    <parent link="camera_link"/>
    <child link="camera_color_frame"/>
  </joint>
  <link name="camera_color_frame"/>
  <joint name="camera_color_optical_joint" type="fixed">
    <origin rpy="-1.5707963267948966 0 -1.5707963267948966" xyz="0 0 0"/>
    <parent link="camera_color_frame"/>
    <child link="camera_color_optical_frame"/>
  </joint>
  <link name="camera_color_optical_frame"/>
  <link name="camera_accel_frame"/>
  <link name="camera_accel_optical_frame"/>
  <link name="camera_gyro_frame"/>
  <link name="camera_gyro_optical_frame"/>
  <joint name="camera_accel_joint" type="fixed">
    <origin rpy="0 0 0" xyz="-0.01174 -0.00552 0.0051"/>
    <parent link="camera_link"/>
    <child link="camera_accel_frame"/>
  </joint>
  <joint name="camera_accel_optical_joint" type="fixed">
    <origin rpy="-1.5707963267948966 0 -1.5707963267948966" xyz="0 0 0"/>
    <parent link="camera_accel_frame"/>
    <child link="camera_accel_optical_frame"/>
  </joint>
  <joint name="camera_gyro_joint" type="fixed">
    <origin rpy="0 0 0" xyz="-0.01174 -0.00552 0.0051"/>
    <parent link="camera_link"/>
    <child link="camera_gyro_frame"/>
  </joint>
  <joint name="camera_gyro_optical_joint" type="fixed">
    <origin rpy="-1.5707963267948966 0 -1.5707963267948966" xyz="0 0 0"/>
    <parent link="camera_gyro_frame"/>
    <child link="camera_gyro_optical_frame"/>
  </joint>
  <link name="world"/>
  <joint name="dummy_joint" type="fixed">
    <parent link="world"/>
    <child link="pedestal_v1_link"/>
    <origin rpy="0.0 0.0 0.0" xyz="0.0 0.0 0.0"/>
  </joint>
  <link name="right_dummy_link"/>
  <joint name="right_dummy_joint" type="fixed">
    <parent link="right_dummy_link"/>
    <child link="right_oparm_link1"/>
  </joint>
  <link name="right_oparm_link1">
    <inertial>
      <origin rpy="0 0 0" xyz="-0.0010128150688448064 0.00011921310475708836 -0.03180504460041544"/>
      <mass value="1.199854606490333"/>
      <inertia ixx="0.001184" ixy="-5e-06" ixz="-3.5e-05" iyy="0.00101" iyz="-8e-06" izz="0.001542"/>
    </inertial>
    <visual>
      <origin rpy="0 0 0" xyz="0 0 0"/>
      <geometry>
        <mesh filename="package://openarm_v1_description/meshes/base_link.stl" scale="0.001 0.001 0.001"/>
      </geometry>
      <material name="silver"/>
    </visual>
    <collision>
      <origin rpy="0 0 0" xyz="0 0 0"/>
      <geometry>
        <mesh filename="package://openarm_v1_description/meshes/base_link.stl" scale="0.001 0.001 0.001"/>
      </geometry>
    </collision>
  </link>
  <link name="right_oparm_link2_1">
    <inertial>
      <origin rpy="0 0 0" xyz="-0.0012074754655398907 3.2777381724620495e-05 0.05528470264561512"/>
      <mass value="1.1000847398831186"/>
      <inertia ixx="0.001407" ixy="-1e-06" ixz="-1.1e-05" iyy="0.001051" iyz="-0.0" izz="0.000834"/>
    </inertial>
    <visual>
      <origin rpy="0 0 0" xyz="6.4e-05 3.9e-05 7.4e-05"/>
      <geometry>
        <mesh filename="package://openarm_v1_description/meshes/oparm_link2_1.stl" scale="0.001 0.001 0.001"/>
      </geometry>
      <material name="silver"/>
    </visual>
    <collision>
      <origin rpy="0 0 0" xyz="6.4e-05 3.9e-05 7.4e-05"/>
      <geometry>
        <mesh filename="package://openarm_v1_description/meshes/oparm_link2_1.stl" scale="0.001 0.001 0.001"/>
      </geometry>
    </collision>
  </link>
  <link name="right_oparm_link3_1">
    <inertial>
      <origin rpy="0 0 0" xyz="0.01121664780902543 1.3328249549549094e-05 0.040881711980061415"/>
      <mass value="0.2517618223062059"/>
      <inertia ixx="0.000191" ixy="-0.0" ixz="-6.2e-05" iyy="0.000222" iyz="-0.0" izz="0.000115"/>
    </inertial>
    <visual>
      <origin rpy="0 0 0" xyz="0.030164 7.5e-05 -0.059926"/>
      <geometry>
        <mesh filename="package://openarm_v1_description/meshes/oparm_link3_1.stl" scale="0.001 0.001 0.001"/>
      </geometry>
      <material name="silver"/>
    </visual>
    <collision>
      <origin rpy="0 0 0" xyz="0.030164 7.5e-05 -0.059926"/>
      <geometry>
        <mesh filename="package://openarm_v1_description/meshes/oparm_link3_1.stl" scale="0.001 0.001 0.001"/>
      </geometry>
    </collision>
  </link>
  <link name="right_oparm_link4_1">
    <inertial>
      <origin rpy="0 0 0" xyz="-0.0007615058947238776 0.0008537439948917441 0.09243691252183486"/>
      <mass value="0.8795120731547696"/>
      <inertia ixx="0.003872" ixy="0.0" ixz="8e-06" iyy="0.003785" iyz="-4.3e-05" izz="0.000459"/>
    </inertial>
    <visual>
      <origin rpy="0 0 0" xyz="6.4e-05 3.9e-05 -0.126176"/>
      <geometry>
        <mesh filename="package://openarm_v1_description/meshes/oparm_link4_1.stl" scale="0.001 0.001 0.001"/>
      </geometry>
      <material name="silver"/>
    </visual>
    <collision>
      <origin rpy="0 0 0" xyz="6.4e-05 3.9e-05 -0.126176"/>
      <geometry>
        <mesh filename="package://openarm_v1_description/meshes/oparm_link4_1.stl" scale="0.001 0.001 0.001"/>
      </geometry>
    </collision>
  </link>
  <link name="right_oparm_link5_1">
    <inertial>
      <origin rpy="0 0 0" xyz="-0.0013357751355886956 -0.030369405447056 0.06320013521798368"/>
      <mass value="0.5098534566833373"/>
      <inertia ixx="0.000623" ixy="-1e-06" ixz="-1.9e-05" iyy="0.000511" iyz="3.8e-05" izz="0.000334"/>
    </inertial>
    <visual>
      <origin rpy="0 0 0" xyz="0.000103 -0.031461 -0.279926"/>
      <geometry>
        <mesh filename="package://openarm_v1_description/meshes/oparm_link5_1.stl" scale="0.001 0.001 0.001"/>
      </geometry>
      <material name="silver"/>
    </visual>
    <collision>
      <origin rpy="0 0 0" xyz="0.000103 -0.031461 -0.279926"/>
      <geometry>
        <mesh filename="package://openarm_v1_description/meshes/oparm_link5_1.stl" scale="0.001 0.001 0.001"/>
      </geometry>
    </collision>
  </link>
  <link name="right_oparm_link6_1">
    <inertial>
      <origin rpy="0 0 0" xyz="-0.0021201729515073105 -0.00062709480879269 0.04528877679278359"/>
      <mass value="0.4900322801663895"/>
      <inertia ixx="0.000352" ixy="1.2e-05" ixz="-1.4e-05" iyy="0.000379" iyz="1.5e-05" izz="0.000234"/>
    </inertial>
    <visual>
      <origin rpy="0 0 0" xyz="6.4e-05 3.9e-05 -0.375426"/>
      <geometry>
        <mesh filename="package://openarm_v1_description/meshes/oparm_link6_1.stl" scale="0.001 0.001  0.001"/>
      </geometry>
      <material name="silver"/>
    </visual>
    <collision>
      <origin rpy="0 0 0" xyz="6.4e-05 3.9e-05 -0.375426"/>
      <geometry>
        <mesh filename="package://openarm_v1_description/meshes/oparm_link6_1.stl" scale="0.001 0.001  0.001"/>
      </geometry>
    </collision>
  </link>
  <link name="right_oparm_link7_1">
    <inertial>
      <origin rpy="0 0 0" xyz="-0.03713023470335729 0.00035983890089288836 -8.108153514163607e-05"/>
      <mass value="0.3593684115765714"/>
      <inertia ixx="0.000146" ixy="4e-06" ixz="-0.0" iyy="0.000159" iyz="1e-06" izz="0.000162"/>
    </inertial>
    <visual>
      <origin rpy="0 0 0" xyz="-0.037436 -7e-06 -0.495926"/>
      <geometry>
        <mesh filename="package://openarm_v1_description/meshes/oparm_link7_1.stl" scale="0.001 0.001 0.001"/>
      </geometry>
      <material name="silver"/>
    </visual>
    <collision>
      <origin rpy="0 0 0" xyz="-0.037436 -7e-06 -0.495926"/>
      <geometry>
        <mesh filename="package://openarm_v1_description/meshes/oparm_link7_1.stl" scale="0.001 0.001 0.001"/>
      </geometry>
    </collision>
  </link>
  <link name="right_oparm_link8_1">
    <inertial>
      <origin rpy="0 0 0" xyz="-4.621208532881523e-05 -0.014878395014230248 0.1108487501579852"/>
      <mass value="1.0519344947868502"/>
      <inertia ixx="0.000541" ixy="0.0" ixz="-1e-06" iyy="0.000436" iyz="6.2e-05" izz="0.000282"/>
    </inertial>
    <visual>
      <origin rpy="0 0 0" xyz="8.9e-05 -0.020461 -0.495926"/>
      <geometry>
        <mesh filename="package://openarm_v1_description/meshes/oparm_link8_1.stl" scale="0.001 0.001 0.001"/>
      </geometry>
      <material name="silver"/>
    </visual>
    <collision>
      <origin rpy="0 0 0" xyz="8.9e-05 -0.020461 -0.495926"/>
      <geometry>
        <mesh filename="package://openarm_v1_description/meshes/oparm_link8_1.stl" scale="0.001 0.001 0.001"/>
      </geometry>
    </collision>
  </link>
  <link name="right_gripper_center"/>
  <link name="right_oparm_link_gripper1_1">
    <inertial>
      <origin rpy="0 0 0" xyz="-0.46648908387963345 0.5103204691805678 0.4070117217536271"/>
      <mass value="0.2697206045576214"/>
      <inertia ixx="0.000188" ixy="1e-06" ixz="2.2e-05" iyy="0.000207" iyz="2e-05" izz="9.1e-05"/>
    </inertial>
    <visual>
      <origin rpy="0 0 0" xyz="-0.469674 0.446194 -0.22199"/>
      <geometry>
        <mesh filename="package://openarm_v1_description/meshes/oparm_link_gripper1_1.stl" scale="0.001 0.001 0.001"/>
      </geometry>
      <material name="silver"/>
    </visual>
    <collision>
      <origin rpy="0 0 0" xyz="-0.469674 0.446194 -0.22199"/>
      <geometry>
        <mesh filename="package://openarm_v1_description/meshes/oparm_link_gripper1_1.stl" scale="0.001 0.001 0.001"/>
      </geometry>
    </collision>
  </link>
  <link name="right_oparm_link_gripper2_1">
    <inertial>
      <origin rpy="0 0 0" xyz="-0.4790039954788485 0.3826938133089908 0.4069900240158981"/>
      <mass value="0.26972369116983347"/>
      <inertia ixx="0.00019" ixy="1e-06" ixz="-2.4e-05" iyy="0.000211" iyz="-2e-05" izz="9.3e-05"/>
    </inertial>
    <visual>
      <origin rpy="0 0 0" xyz="-0.475748 0.440106 -0.222001"/>
      <geometry>
        <mesh filename="package://openarm_v1_description/meshes/oparm_link_gripper2_1.stl" scale="0.001 0.001 0.001"/>
      </geometry>
      <material name="silver"/>
    </visual>
    <collision>
      <origin rpy="0 0 0" xyz="-0.475748 0.440106 -0.222001"/>
      <geometry>
        <mesh filename="package://openarm_v1_description/meshes/oparm_link_gripper2_1.stl" scale="0.001 0.001 0.001"/>
      </geometry>
    </collision>
  </link>
  <joint name="right_oparm_joint1" type="revolute">
    <origin rpy="0 0 0" xyz="-6.4e-05 -3.9e-05 -7.4e-05"/>
    <parent link="right_oparm_link1"/>
    <child link="right_oparm_link2_1"/>
    <axis xyz="0.0 0.0 1.0"/>
    <limit effort="100" lower="-1.396263" upper="3.490659" velocity="100"/>
  </joint>
  <joint name="right_oparm_joint2" type="revolute">
    <origin rpy="1.5707963267948966 0 0" xyz="-0.0301 -3.6e-05 0.06"/>
    <parent link="right_oparm_link2_1"/>
    <child link="right_oparm_link3_1"/>
    <axis xyz="-1.0 0.0 0.0"/>
    <limit effort="100" lower="-0.17453267320510335" upper="3.3161253267948965" velocity="100"/>
  </joint>
  <joint name="right_oparm_joint3" type="revolute">
    <origin rpy="0 0 0" xyz="0.0301 3.6e-05 0.06625"/>
    <parent link="right_oparm_link3_1"/>
    <child link="right_oparm_link4_1"/>
    <axis xyz="-0.0 0.0 1.0"/>
    <limit effort="100" lower="-1.570796" upper="1.570796" velocity="100"/>
  </joint>
  <joint name="right_oparm_joint4" type="revolute">
    <origin rpy="0 0 0" xyz="-3.9e-05 0.0315 0.15375"/>
    <parent link="right_oparm_link4_1"/>
    <child link="right_oparm_link5_1"/>
    <axis xyz="0.0 1.0 0.0"/>
    <limit effort="100" lower="0.0" upper="2.443461" velocity="100"/>
  </joint>
  <joint name="right_oparm_joint5" type="revolute">
    <origin rpy="0 0 0" xyz="3.9e-05 -0.0315 0.0955"/>
    <parent link="right_oparm_link5_1"/>
    <child link="right_oparm_link6_1"/>
    <axis xyz="0.0 -0.0 1.0"/>
    <limit effort="100" lower="-1.570796" upper="1.570796" velocity="100"/>
  </joint>
  <joint name="right_oparm_joint6" type="revolute">
    <origin rpy="0 0 0" xyz="0.0375 4.6e-05 0.1205"/>
    <parent link="right_oparm_link6_1"/>
    <child link="right_oparm_link7_1"/>
    <axis xyz="1.0 0.0 0.0"/>
    <limit effort="100" lower="-0.785398" upper="0.785398" velocity="100"/>
  </joint>
  <joint name="right_oparm_joint7" type="revolute">
    <origin rpy="0 0 0" xyz="-0.037525 0.020454 0.0"/>
    <parent link="right_oparm_link7_1"/>
    <child link="right_oparm_link8_1"/>
    <axis xyz="0.0 1.0 0.0"/>
    <limit effort="100" lower="-1.570796" upper="1.570796" velocity="100"/>
  </joint>
  <joint name="right_oparm_joint_gripper1" type="prismatic">
    <origin rpy="0 0 0" xyz="0.469763 -0.466655 -0.273936"/>
    <parent link="right_oparm_link8_1"/>
    <child link="right_oparm_link_gripper1_1"/>
    <axis xyz="0.0 -1.0 -0.0"/>
    <limit effort="100" lower="0.0" upper="0.043" velocity="100"/>
  </joint>
  <joint name="right_oparm_joint_gripper2" type="prismatic">
    <origin rpy="0 0 0" xyz="0.475837 -0.460567 -0.273925"/>
    <parent link="right_oparm_link8_1"/>
    <child link="right_oparm_link_gripper2_1"/>
    <axis xyz="0.0 1.0 0.0"/>
    <limit effort="100" lower="0.0" upper="0.043" velocity="100"/>
    <mimic joint="right_oparm_joint_gripper1" multiplier="1.0" offset="0.0"/>
  </joint>
  <joint name="right_virtual_gripper_center" type="fixed">
    <parent link="right_oparm_link8_1"/>
    <child link="right_gripper_center"/>
    <origin rpy="0 0 0" xyz="0.0 0.00 0.13"/>
  </joint>
  <joint name="right_fixed1" type="fixed">
    <parent link="pedestal_v1_link"/>
    <child link="right_dummy_link"/>
    <origin rpy="1.5707963267948966 0.0 0.0" xyz="0.0 -0.13 0.85"/>
  </joint>
  <link name="left_dummy_link"/>
  <joint name="left_dummy_joint" type="fixed">
    <parent link="left_dummy_link"/>
    <child link="left_oparm_link1"/>
  </joint>
  <link name="left_oparm_link1">
    <inertial>
      <origin rpy="0 0 0" xyz="-0.0010128150688448064 0.00011921310475708836 -0.03180504460041544"/>
      <mass value="1.199854606490333"/>
      <inertia ixx="0.001184" ixy="-5e-06" ixz="-3.5e-05" iyy="0.00101" iyz="-8e-06" izz="0.001542"/>
    </inertial>
    <visual>
      <origin rpy="0 0 0" xyz="0 0 0"/>
      <geometry>
        <mesh filename="package://openarm_v1_description/meshes/base_link.stl" scale="0.001 -0.001 0.001"/>
      </geometry>
      <material name="silver"/>
    </visual>
    <collision>
      <origin rpy="0 0 0" xyz="0 0 0"/>
      <geometry>
        <mesh filename="package://openarm_v1_description/meshes/base_link.stl" scale="0.001 -0.001 0.001"/>
      </geometry>
    </collision>
  </link>
  <link name="left_oparm_link2_1">
    <inertial>
      <origin rpy="0 0 0" xyz="-0.0012074754655398907 3.2777381724620495e-05 0.05528470264561512"/>
      <mass value="1.1000847398831186"/>
      <inertia ixx="0.001407" ixy="-1e-06" ixz="-1.1e-05" iyy="0.001051" iyz="-0.0" izz="0.000834"/>
    </inertial>
    <visual>
      <origin rpy="0 0 0" xyz="6.4e-05 3.9e-05 7.4e-05"/>
      <geometry>
        <mesh filename="package://openarm_v1_description/meshes/oparm_link2_1.stl" scale="0.001 -0.001 0.001"/>
      </geometry>
      <material name="silver"/>
    </visual>
    <collision>
      <origin rpy="0 0 0" xyz="6.4e-05 3.9e-05 7.4e-05"/>
      <geometry>
        <mesh filename="package://openarm_v1_description/meshes/oparm_link2_1.stl" scale="0.001 -0.001 0.001"/>
      </geometry>
    </collision>
  </link>
  <link name="left_oparm_link3_1">
    <inertial>
      <origin rpy="0 0 0" xyz="0.01121664780902543 1.3328249549549094e-05 0.040881711980061415"/>
      <mass value="0.2517618223062059"/>
      <inertia ixx="0.000191" ixy="-0.0" ixz="-6.2e-05" iyy="0.000222" iyz="-0.0" izz="0.000115"/>
    </inertial>
    <visual>
      <origin rpy="0 0 0" xyz="0.030164 7.5e-05 -0.059926"/>
      <geometry>
        <mesh filename="package://openarm_v1_description/meshes/oparm_link3_1.stl" scale="0.001 -0.001 0.001"/>
      </geometry>
      <material name="silver"/>
    </visual>
    <collision>
      <origin rpy="0 0 0" xyz="0.030164 7.5e-05 -0.059926"/>
      <geometry>
        <mesh filename="package://openarm_v1_description/meshes/oparm_link3_1.stl" scale="0.001 -0.001 0.001"/>
      </geometry>
    </collision>
  </link>
  <link name="left_oparm_link4_1">
    <inertial>
      <origin rpy="0 0 0" xyz="-0.0007615058947238776 0.0008537439948917441 0.09243691252183486"/>
      <mass value="0.8795120731547696"/>
      <inertia ixx="0.003872" ixy="0.0" ixz="8e-06" iyy="0.003785" iyz="-4.3e-05" izz="0.000459"/>
    </inertial>
    <visual>
      <origin rpy="0 0 0" xyz="6.4e-05 3.9e-05 -0.126176"/>
      <geometry>
        <mesh filename="package://openarm_v1_description/meshes/oparm_link4_1.stl" scale="0.001 -0.001 0.001"/>
      </geometry>
      <material name="silver"/>
    </visual>
    <collision>
      <origin rpy="0 0 0" xyz="6.4e-05 3.9e-05 -0.126176"/>
      <geometry>
        <mesh filename="package://openarm_v1_description/meshes/oparm_link4_1.stl" scale="0.001 -0.001 0.001"/>
      </geometry>
    </collision>
  </link>
  <link name="left_oparm_link5_1">
    <inertial>
      <origin rpy="0 0 0" xyz="-0.0013357751355886956 -0.030369405447056 0.06320013521798368"/>
      <mass value="0.5098534566833373"/>
      <inertia ixx="0.000623" ixy="-1e-06" ixz="-1.9e-05" iyy="0.000511" iyz="3.8e-05" izz="0.000334"/>
    </inertial>
    <visual>
      <origin rpy="0 0 0" xyz="0.000103 -0.031461 -0.279926"/>
      <geometry>
        <mesh filename="package://openarm_v1_description/meshes/oparm_link5_1.stl" scale="0.001 -0.001 0.001"/>
      </geometry>
      <material name="silver"/>
    </visual>
    <collision>
      <origin rpy="0 0 0" xyz="0.000103 -0.031461 -0.279926"/>
      <geometry>
        <mesh filename="package://openarm_v1_description/meshes/oparm_link5_1.stl" scale="0.001 -0.001 0.001"/>
      </geometry>
    </collision>
  </link>
  <link name="left_oparm_link6_1">
    <inertial>
      <origin rpy="0 0 0" xyz="-0.0021201729515073105 -0.00062709480879269 0.04528877679278359"/>
      <mass value="0.4900322801663895"/>
      <inertia ixx="0.000352" ixy="1.2e-05" ixz="-1.4e-05" iyy="0.000379" iyz="1.5e-05" izz="0.000234"/>
    </inertial>
    <visual>
      <origin rpy="0 0 0" xyz="6.4e-05 3.9e-05 -0.375426"/>
      <geometry>
        <mesh filename="package://openarm_v1_description/meshes/oparm_link6_1.stl" scale="0.001 -0.001  0.001"/>
      </geometry>
      <material name="silver"/>
    </visual>
    <collision>
      <origin rpy="0 0 0" xyz="6.4e-05 3.9e-05 -0.375426"/>
      <geometry>
        <mesh filename="package://openarm_v1_description/meshes/oparm_link6_1.stl" scale="0.001 -0.001  0.001"/>
      </geometry>
    </collision>
  </link>
  <link name="left_oparm_link7_1">
    <inertial>
      <origin rpy="0 0 0" xyz="-0.03713023470335729 0.00035983890089288836 -8.108153514163607e-05"/>
      <mass value="0.3593684115765714"/>
      <inertia ixx="0.000146" ixy="4e-06" ixz="-0.0" iyy="0.000159" iyz="1e-06" izz="0.000162"/>
    </inertial>
    <visual>
      <origin rpy="0 0 0" xyz="-0.037436 -7e-06 -0.495926"/>
      <geometry>
        <mesh filename="package://openarm_v1_description/meshes/oparm_link7_1.stl" scale="0.001 0.001 0.001"/>
      </geometry>
      <material name="silver"/>
    </visual>
    <collision>
      <origin rpy="0 0 0" xyz="-0.037436 -7e-06 -0.495926"/>
      <geometry>
        <mesh filename="package://openarm_v1_description/meshes/oparm_link7_1.stl" scale="0.001 0.001 0.001"/>
      </geometry>
    </collision>
  </link>
  <link name="left_oparm_link8_1">
    <inertial>
      <origin rpy="0 0 0" xyz="-4.621208532881523e-05 -0.014878395014230248 0.1108487501579852"/>
      <mass value="1.0519344947868502"/>
      <inertia ixx="0.000541" ixy="0.0" ixz="-1e-06" iyy="0.000436" iyz="6.2e-05" izz="0.000282"/>
    </inertial>
    <visual>
      <origin rpy="0 0 0" xyz="8.9e-05 -0.020461 -0.495926"/>
      <geometry>
        <mesh filename="package://openarm_v1_description/meshes/oparm_link8_1.stl" scale="0.001 -0.001 0.001"/>
      </geometry>
      <material name="silver"/>
    </visual>
    <collision>
      <origin rpy="0 0 0" xyz="8.9e-05 -0.020461 -0.495926"/>
      <geometry>
        <mesh filename="package://openarm_v1_description/meshes/oparm_link8_1.stl" scale="0.001 -0.001 0.001"/>
      </geometry>
    </collision>
  </link>
  <link name="left_gripper_center"/>
  <link name="left_oparm_link_gripper1_1">
    <inertial>
      <origin rpy="0 0 0" xyz="-0.46648908387963345 0.5103204691805678 0.4070117217536271"/>
      <mass value="0.2697206045576214"/>
      <inertia ixx="0.000188" ixy="1e-06" ixz="2.2e-05" iyy="0.000207" iyz="2e-05" izz="9.1e-05"/>
    </inertial>
    <visual>
      <origin rpy="0 0 0" xyz="-0.469674 0.446194 -0.22199"/>
      <geometry>
        <mesh filename="package://openarm_v1_description/meshes/oparm_link_gripper1_1.stl" scale="0.001 0.001 0.001"/>
      </geometry>
      <material name="silver"/>
    </visual>
    <collision>
      <origin rpy="0 0 0" xyz="-0.469674 0.446194 -0.22199"/>
      <geometry>
        <mesh filename="package://openarm_v1_description/meshes/oparm_link_gripper1_1.stl" scale="0.001 0.001 0.001"/>
      </geometry>
    </collision>
  </link>
  <link name="left_oparm_link_gripper2_1">
    <inertial>
      <origin rpy="0 0 0" xyz="-0.4790039954788485 0.3826938133089908 0.4069900240158981"/>
      <mass value="0.26972369116983347"/>
      <inertia ixx="0.00019" ixy="1e-06" ixz="-2.4e-05" iyy="0.000211" iyz="-2e-05" izz="9.3e-05"/>
    </inertial>
    <visual>
      <origin rpy="0 0 0" xyz="-0.475748 0.440106 -0.222001"/>
      <geometry>
        <mesh filename="package://openarm_v1_description/meshes/oparm_link_gripper2_1.stl" scale="0.001 0.001 0.001"/>
      </geometry>
      <material name="silver"/>
    </visual>
    <collision>
      <origin rpy="0 0 0" xyz="-0.475748 0.440106 -0.222001"/>
      <geometry>
        <mesh filename="package://openarm_v1_description/meshes/oparm_link_gripper2_1.stl" scale="0.001 0.001 0.001"/>
      </geometry>
    </collision>
  </link>
  <joint name="left_oparm_joint1" type="revolute">
    <origin rpy="0 0 0" xyz="-6.4e-05 -3.9e-05 -7.4e-05"/>
    <parent link="left_oparm_link1"/>
    <child link="left_oparm_link2_1"/>
    <axis xyz="0.0 0.0 1.0"/>
    <limit effort="100" lower="-3.490659" upper="1.396263" velocity="100"/>
  </joint>
  <joint name="left_oparm_joint2" type="revolute">
    <origin rpy="-1.5707963267948966 0 0" xyz="-0.0301 -3.6e-05 0.06"/>
    <parent link="left_oparm_link2_1"/>
    <child link="left_oparm_link3_1"/>
    <axis xyz="-1.0 0.0 0.0"/>
    <limit effort="100" lower="-3.3161253267948965" upper="0.17453267320510335" velocity="100"/>
  </joint>
  <joint name="left_oparm_joint3" type="revolute">
    <origin rpy="0 0 0" xyz="0.0301 3.6e-05 0.06625"/>
    <parent link="left_oparm_link3_1"/>
    <child link="left_oparm_link4_1"/>
    <axis xyz="-0.0 0.0 1.0"/>
    <limit effort="100" lower="-1.570796" upper="1.570796" velocity="100"/>
  </joint>
  <joint name="left_oparm_joint4" type="revolute">
    <origin rpy="0 0 0" xyz="-3.9e-05 0.0315 0.15375"/>
    <parent link="left_oparm_link4_1"/>
    <child link="left_oparm_link5_1"/>
    <axis xyz="0.0 1.0 0.0"/>
    <limit effort="100" lower="0.0" upper="2.443461" velocity="100"/>
  </joint>
  <joint name="left_oparm_joint5" type="revolute">
    <origin rpy="0 0 0" xyz="3.9e-05 -0.0315 0.0955"/>
    <parent link="left_oparm_link5_1"/>
    <child link="left_oparm_link6_1"/>
    <axis xyz="0.0 -0.0 1.0"/>
    <limit effort="100" lower="-1.570796" upper="1.570796" velocity="100"/>
  </joint>
  <joint name="left_oparm_joint6" type="revolute">
    <origin rpy="0 0 0" xyz="0.0375 4.6e-05 0.1205"/>
    <parent link="left_oparm_link6_1"/>
    <child link="left_oparm_link7_1"/>
    <axis xyz="1.0 0.0 0.0"/>
    <limit effort="100" lower="-0.785398" upper="0.785398" velocity="100"/>
  </joint>
  <joint name="left_oparm_joint7" type="revolute">
    <origin rpy="0 0 0" xyz="-0.037525 0.020454 0.0"/>
    <parent link="left_oparm_link7_1"/>
    <child link="left_oparm_link8_1"/>
    <axis xyz="0.0 -1.0 0.0"/>
    <limit effort="100" lower="-1.570796" upper="1.570796" velocity="100"/>
  </joint>
  <joint name="left_oparm_joint_gripper1" type="prismatic">
    <origin rpy="0 0 0" xyz="0.469763 -0.466655 -0.273936"/>
    <parent link="left_oparm_link8_1"/>
    <child link="left_oparm_link_gripper1_1"/>
    <axis xyz="0.0 -1.0 -0.0"/>
    <limit effort="100" lower="0.0" upper="0.043" velocity="100"/>
  </joint>
  <joint name="left_oparm_joint_gripper2" type="prismatic">
    <origin rpy="0 0 0" xyz="0.475837 -0.460567 -0.273925"/>
    <parent link="left_oparm_link8_1"/>
    <child link="left_oparm_link_gripper2_1"/>
    <axis xyz="0.0 1.0 0.0"/>
    <limit effort="100" lower="0.0" upper="0.043" velocity="100"/>
    <mimic joint="left_oparm_joint_gripper1" multiplier="1.0" offset="0.0"/>
  </joint>
  <joint name="left_virtual_gripper_center" type="fixed">
    <parent link="left_oparm_link8_1"/>
    <child link="left_gripper_center"/>
    <origin rpy="0 0 0" xyz="0.0 0.00 0.13"/>
  </joint>
  <joint name="left_fixed1" type="fixed">
    <parent link="pedestal_v1_link"/>
    <child link="left_dummy_link"/>
    <origin rpy="-1.5707963267948966 0.0 0.0" xyz="0.0 0.13 0.85"/>
  </joint>
  <ros2_control name="right_RightOpenArm_v1_HW" type="system">
    <hardware>
      <plugin>openarm_hardware/OpenArm_v1_HW</plugin>
      <param name="prefix">right_</param>
      <param name="can_device">can0</param>
    </hardware>
    <joint name="right_oparm_joint1">
      <command_interface name="position"/>
      <command_interface name="velocity"/>
      <command_interface name="effort"/>
      <state_interface name="position"/>
      <state_interface name="velocity"/>
      <state_interface name="effort"/>
    </joint>
    <joint name="right_oparm_joint2">
      <command_interface name="position"/>
      <command_interface name="velocity"/>
      <command_interface name="effort"/>
      <state_interface name="position"/>
      <state_interface name="velocity"/>
      <state_interface name="effort"/>
    </joint>
    <joint name="right_oparm_joint3">
      <command_interface name="position"/>
      <command_interface name="velocity"/>
      <command_interface name="effort"/>
      <state_interface name="position"/>
      <state_interface name="velocity"/>
      <state_interface name="effort"/>
    </joint>
    <joint name="right_oparm_joint4">
      <command_interface name="position"/>
      <command_interface name="velocity"/>
      <command_interface name="effort"/>
      <state_interface name="position"/>
      <state_interface name="velocity"/>
      <state_interface name="effort"/>
    </joint>
    <joint name="right_oparm_joint5">
      <command_interface name="position"/>
      <command_interface name="velocity"/>
      <command_interface name="effort"/>
      <state_interface name="position"/>
      <state_interface name="velocity"/>
      <state_interface name="effort"/>
    </joint>
    <joint name="right_oparm_joint6">
      <command_interface name="position"/>
      <command_interface name="velocity"/>
      <command_interface name="effort"/>
      <state_interface name="position"/>
      <state_interface name="velocity"/>
      <state_interface name="effort"/>
    </joint>
    <joint name="right_oparm_joint7">
      <command_interface name="position"/>
      <command_interface name="velocity"/>
      <command_interface name="effort"/>
      <state_interface name="position"/>
      <state_interface name="velocity"/>
      <state_interface name="effort"/>
    </joint>
    <joint name="right_oparm_joint_gripper2">
      <command_interface name="position"/>
      <state_interface name="position"/>
      <state_interface name="velocity"/>
    </joint>
  </ros2_control>
  <ros2_control name="left_LeftOpenArm_v1_HW" type="system">
    <hardware>
      <plugin>openarm_hardware/OpenArm_v1_HW</plugin>
      <param name="prefix">left_</param>
      <param name="can_device">can1</param>
    </hardware>
    <joint name="left_oparm_joint1">
      <command_interface name="position"/>
      <command_interface name="velocity"/>
      <command_interface name="effort"/>
      <state_interface name="position"/>
      <state_interface name="velocity"/>
      <state_interface name="effort"/>
    </joint>
    <joint name="left_oparm_joint2">
      <command_interface name="position"/>
      <command_interface name="velocity"/>
      <command_interface name="effort"/>
      <state_interface name="position"/>
      <state_interface name="velocity"/>
      <state_interface name="effort"/>
    </joint>
    <joint name="left_oparm_joint3">
      <command_interface name="position"/>
      <command_interface name="velocity"/>
      <command_interface name="effort"/>
      <state_interface name="position"/>
      <state_interface name="velocity"/>
      <state_interface name="effort"/>
    </joint>
    <joint name="left_oparm_joint4">
      <command_interface name="position"/>
      <command_interface name="velocity"/>
      <command_interface name="effort"/>
      <state_interface name="position"/>
      <state_interface name="velocity"/>
      <state_interface name="effort"/>
    </joint>
    <joint name="left_oparm_joint5">
      <command_interface name="position"/>
      <command_interface name="velocity"/>
      <command_interface name="effort"/>
      <state_interface name="position"/>
      <state_interface name="velocity"/>
      <state_interface name="effort"/>
    </joint>
    <joint name="left_oparm_joint6">
      <command_interface name="position"/>
      <command_interface name="velocity"/>
      <command_interface name="effort"/>
      <state_interface name="position"/>
      <state_interface name="velocity"/>
      <state_interface name="effort"/>
    </joint>
    <joint name="left_oparm_joint7">
      <command_interface name="position"/>
      <command_interface name="velocity"/>
      <command_interface name="effort"/>
      <state_interface name="position"/>
      <state_interface name="velocity"/>
      <state_interface name="effort"/>
    </joint>
    <joint name="left_oparm_joint_gripper2">
      <command_interface name="position"/>
      <state_interface name="position"/>
      <state_interface name="velocity"/>
    </joint>
  </ros2_control>
</robot>
