<?xml version="1.0" ?>
<!-- =================================================================================== -->
<!-- |    This document was autogenerated by xacro from v10.urdf.xacro                 | -->
<!-- |    EDITING THIS FILE BY HAND IS NOT RECOMMENDED                                 | -->
<!-- =================================================================================== -->
<robot name="openarm">
  <!-- arm_type: Namespace of the robot arm. Serves to differentiate between arms in case of multiple instances. -->
  <!-- joint_limits: description of the joint limits that comes from a YAML file. Example definition: ${xacro.load_yaml('$(find openarm_description)/robots/fr3/joint_limits.yaml')} -->
  <!-- kinematics: description of the kinematics that comes from a YAML file. Example definition: ${xacro.load_yaml('$(find openarm_description)/robots/fr3/kinematics.yaml')} -->
  <!-- inertials: description of the inertials that comes from a YAML file. Example definition: ${xacro.load_yaml('$(find openarm_description)/robots/fr3/inertials.yaml')} -->
  <!-- Define a property that defaults to 'arm_prefix_arm_type' concatenated with an underscore if 'no_prefix' is not set -->
  <link name="openarm_link0">
    <visual name="openarm_link0_visual">
      <origin rpy="0.0 0.0 0.0" xyz="0.0 0.0 0.0"/>
      <geometry>
        <mesh filename="package://openarm_description/meshes/arm/v10/visual/link0.dae" scale="0.001 -0.001 0.001"/>
      </geometry>
    </visual>
    <collision name="openarm_link0_collision">
      <origin rpy="0.0 0.0 0.0" xyz="0.0 0.0 0.0"/>
      <geometry>
        <mesh filename="package://openarm_description/meshes/arm/v10/collision/link0_symp.stl" scale="0.001 -0.001 0.001"/>
        <!-- <mesh filename="package://openarm_description/meshes/arm/${arm_type}/collision/${name}.stl" scale="0.001 0.001 0.001" /> -->
      </geometry>
    </collision>
    <inertial>
      <origin rpy="0.0 0.0 0.0" xyz="-0.0009483362816297526 0.0001580207020448382 0.03076860287587199"/>
      <mass value="1.1432284943239561"/>
      <inertia ixx="0.001128" ixy="-4e-06" ixz="-3.3e-05" iyy="0.000962" iyz="-7e-06" izz="0.00147"/>
    </inertial>
  </link>
  <link name="openarm_link1">
    <visual name="openarm_link1_visual">
      <origin rpy="0.0 0.0 0.0" xyz="-0.0 0.0 -0.0625"/>
      <geometry>
        <mesh filename="package://openarm_description/meshes/arm/v10/visual/link1.dae" scale="0.001 -0.001 0.001"/>
      </geometry>
    </visual>
    <collision name="openarm_link1_collision">
      <origin rpy="0.0 0.0 0.0" xyz="-0.0 0.0 -0.0625"/>
      <geometry>
        <mesh filename="package://openarm_description/meshes/arm/v10/collision/link1_symp.stl" scale="0.001 -0.001 0.001"/>
        <!-- <mesh filename="package://openarm_description/meshes/arm/${arm_type}/collision/${name}.stl" scale="0.001 0.001 0.001" /> -->
      </geometry>
    </collision>
    <inertial>
      <origin rpy="0.0 0.0 0.0" xyz="0.0011467657911800769 3.319987657026362e-05 0.05395284380736254"/>
      <mass value="1.1416684646202298"/>
      <inertia ixx="0.001567" ixy="-1e-06" ixz="-2.9e-05" iyy="0.001273" iyz="-0.0" izz="0.001016"/>
    </inertial>
  </link>
  <joint name="openarm_joint1" type="revolute">
    <origin rpy="0 0 0" xyz="0.0 0.0 0.0625"/>
    <parent link="openarm_link0"/>
    <child link="openarm_link1"/>
    <axis xyz="0 0 1"/>
    <limit effort="100" lower="-1.396263" upper="3.490659" velocity="100"/>
  </joint>
  <link name="openarm_link2">
    <visual name="openarm_link2_visual">
      <origin rpy="0.0 0.0 0.0" xyz="0.0301 0.0 -0.1225"/>
      <geometry>
        <mesh filename="package://openarm_description/meshes/arm/v10/visual/link2.dae" scale="0.001 -0.001 0.001"/>
      </geometry>
    </visual>
    <collision name="openarm_link2_collision">
      <origin rpy="0.0 0.0 0.0" xyz="0.0301 0.0 -0.1225"/>
      <geometry>
        <mesh filename="package://openarm_description/meshes/arm/v10/collision/link2_symp.stl" scale="0.001 -0.001 0.001"/>
        <!-- <mesh filename="package://openarm_description/meshes/arm/${arm_type}/collision/${name}.stl" scale="0.001 0.001 0.001" /> -->
      </geometry>
    </collision>
    <inertial>
      <origin rpy="0.0 0.0 0.0" xyz="0.00839629182351943 -2.0145102027597523e-08 0.03256649300522363"/>
      <mass value="0.2775092746011571"/>
      <inertia ixx="0.000359" ixy="-0.0" ixz="-0.000109" iyy="0.000376" iyz="0.0" izz="0.000232"/>
    </inertial>
  </link>
  <joint name="openarm_joint2" type="revolute">
    <origin rpy="0 0 0" xyz="-0.0301 0.0 0.06"/>
    <parent link="openarm_link1"/>
    <child link="openarm_link2"/>
    <axis xyz="-1 0 0"/>
    <limit effort="100" lower="-1.745329" upper="1.745329" velocity="100"/>
  </joint>
  <link name="openarm_link3">
    <visual name="openarm_link3_visual">
      <origin rpy="0.0 0.0 0.0" xyz="-0.0 -0.0 -0.18875"/>
      <geometry>
        <mesh filename="package://openarm_description/meshes/arm/v10/visual/link3.dae" scale="0.001 -0.001 0.001"/>
      </geometry>
    </visual>
    <collision name="openarm_link3_collision">
      <origin rpy="0.0 0.0 0.0" xyz="-0.0 -0.0 -0.18875"/>
      <geometry>
        <mesh filename="package://openarm_description/meshes/arm/v10/collision/link3_symp.stl" scale="0.001 -0.001 0.001"/>
        <!-- <mesh filename="package://openarm_description/meshes/arm/${arm_type}/collision/${name}.stl" scale="0.001 0.001 0.001" /> -->
      </geometry>
    </collision>
    <inertial>
      <origin rpy="0.0 0.0 0.0" xyz="-0.002104752099628911 0.0005549085042607548 0.08847470545721961"/>
      <mass value="1.073863338202347"/>
      <inertia ixx="0.004372" ixy="-0.0" ixz="1.1e-05" iyy="0.004319" iyz="-3.6e-05" izz="0.000661"/>
    </inertial>
  </link>
  <joint name="openarm_joint3" type="revolute">
    <origin rpy="0 0 0" xyz="0.0301 0.0 0.06625"/>
    <parent link="openarm_link2"/>
    <child link="openarm_link3"/>
    <axis xyz="0 0 1"/>
    <limit effort="100" lower="-1.570796" upper="1.570796" velocity="100"/>
  </joint>
  <link name="openarm_link4">
    <visual name="openarm_link4_visual">
      <origin rpy="0.0 0.0 0.0" xyz="0.0 -0.0315 -0.3425"/>
      <geometry>
        <mesh filename="package://openarm_description/meshes/arm/v10/visual/link4.dae" scale="0.001 0.001 0.001"/>
      </geometry>
    </visual>
    <collision name="openarm_link4_collision">
      <origin rpy="0.0 0.0 0.0" xyz="0.0 -0.0315 -0.3425"/>
      <geometry>
        <mesh filename="package://openarm_description/meshes/arm/v10/collision/link4_symp.stl" scale="0.001 0.001 0.001"/>
        <!-- <mesh filename="package://openarm_description/meshes/arm/${arm_type}/collision/${name}.stl" scale="0.001 0.001 0.001" /> -->
      </geometry>
    </collision>
    <inertial>
      <origin rpy="0.0 0.0 0.0" xyz="-0.0029006831074562967 -0.03030575826634669 0.06339637422196209"/>
      <mass value="1.3699337287025453"/>
      <inertia ixx="0.001577" ixy="-5e-06" ixz="-7.5e-05" iyy="0.001346" iyz="0.000108" izz="0.001104"/>
    </inertial>
  </link>
  <joint name="openarm_joint4" type="revolute">
    <origin rpy="0 0 0" xyz="-0.0 0.0315 0.15375"/>
    <parent link="openarm_link3"/>
    <child link="openarm_link4"/>
    <axis xyz="0 1 0"/>
    <limit effort="100" lower="0.0" upper="2.443461" velocity="100"/>
  </joint>
  <link name="openarm_link5">
    <visual name="openarm_link5_visual">
      <origin rpy="0.0 0.0 0.0" xyz="-0.0 -0.0 -0.438"/>
      <geometry>
        <mesh filename="package://openarm_description/meshes/arm/v10/visual/link5.dae" scale="0.001 -0.001 0.001"/>
      </geometry>
    </visual>
    <collision name="openarm_link5_collision">
      <origin rpy="0.0 0.0 0.0" xyz="-0.0 -0.0 -0.438"/>
      <geometry>
        <mesh filename="package://openarm_description/meshes/arm/v10/collision/link5_symp.stl" scale="0.001 -0.001 0.001"/>
        <!-- <mesh filename="package://openarm_description/meshes/arm/${arm_type}/collision/${name}.stl" scale="0.001 0.001 0.001" /> -->
      </geometry>
    </collision>
    <inertial>
      <origin rpy="0.0 0.0 0.0" xyz="-0.003049665024221911 0.0008866902457326625 0.043079803024980934"/>
      <mass value="0.5506588026168502"/>
      <inertia ixx="0.000423" ixy="-8e-06" ixz="6e-06" iyy="0.000445" iyz="-6e-06" izz="0.000324"/>
    </inertial>
  </link>
  <joint name="openarm_joint5" type="revolute">
    <origin rpy="0 0 0" xyz="0.0 -0.0315 0.0955"/>
    <parent link="openarm_link4"/>
    <child link="openarm_link5"/>
    <axis xyz="0 0 1"/>
    <limit effort="100" lower="-1.570796" upper="1.570796" velocity="100"/>
  </joint>
  <link name="openarm_link6">
    <visual name="openarm_link6_visual">
      <origin rpy="0.0 0.0 0.0" xyz="-0.0375 -0.0 -0.5585"/>
      <geometry>
        <mesh filename="package://openarm_description/meshes/arm/v10/visual/link6.dae" scale="0.001 -0.001 0.001"/>
      </geometry>
    </visual>
    <collision name="openarm_link6_collision">
      <origin rpy="0.0 0.0 0.0" xyz="-0.0375 -0.0 -0.5585"/>
      <geometry>
        <mesh filename="package://openarm_description/meshes/arm/v10/collision/link6_symp.stl" scale="0.001 -0.001 0.001"/>
        <!-- <mesh filename="package://openarm_description/meshes/arm/${arm_type}/collision/${name}.stl" scale="0.001 0.001 0.001" /> -->
      </geometry>
    </collision>
    <inertial>
      <origin rpy="0.0 0.0 0.0" xyz="-0.037136587005447405 0.00033230528343419053 -9.498374522309838e-05"/>
      <mass value="0.3540202773187987"/>
      <inertia ixx="0.000143" ixy="4e-06" ixz="0.0" iyy="0.000157" iyz="1e-06" izz="0.000159"/>
    </inertial>
  </link>
  <joint name="openarm_joint6" type="revolute">
    <origin rpy="0 0 0" xyz="0.0375 0.0 0.1205"/>
    <parent link="openarm_link5"/>
    <child link="openarm_link6"/>
    <axis xyz="1 0 0"/>
    <limit effort="100" lower="-0.785398" upper="0.785398" velocity="100"/>
  </joint>
  <link name="openarm_link7">
    <visual name="openarm_link7_visual">
      <origin rpy="0.0 0.0 0.0" xyz="0.0 -0.0 -0.5585"/>
      <geometry>
        <mesh filename="package://openarm_description/meshes/arm/v10/visual/link7.dae" scale="0.001 -0.001 0.001"/>
      </geometry>
    </visual>
    <collision name="openarm_link7_collision">
      <origin rpy="0.0 0.0 0.0" xyz="0.0 -0.0 -0.5585"/>
      <geometry>
        <mesh filename="package://openarm_description/meshes/arm/v10/collision/link7_symp.stl" scale="0.001 -0.001 0.001"/>
        <!-- <mesh filename="package://openarm_description/meshes/arm/${arm_type}/collision/${name}.stl" scale="0.001 0.001 0.001" /> -->
      </geometry>
    </collision>
    <inertial>
      <origin rpy="0.0 0.0 0.0" xyz="6.875510271106056e-05 -0.01766175250761268 0.06651945409987448"/>
      <mass value="0.5499771327380578"/>
      <inertia ixx="0.000639" ixy="0.0" ixz="-0.0" iyy="0.000497" iyz="8.9e-05" izz="0.000342"/>
    </inertial>
  </link>
  <joint name="openarm_joint7" type="revolute">
    <origin rpy="0 0 0" xyz="-0.0375 0.0 0.0"/>
    <parent link="openarm_link6"/>
    <child link="openarm_link7"/>
    <axis xyz="0 1 0"/>
    <limit effort="100" lower="-1.570796" upper="1.570796" velocity="100"/>
  </joint>
  <link name="openarm_link8"/>
  <joint name="openarm_joint8" type="fixed">
    <origin rpy="0 0 0" xyz="1e-06 -0.098 0.114501"/>
    <parent link="openarm_link7"/>
    <child link="openarm_link8"/>
  </joint>
  <ros2_control name="openarmHardwareInterface" type="system">
    <hardware>
      <param name="arm_type">v10</param>
      <param name="prefix"></param>
      <plugin>openarm_hardware/openarmHardwareInterface</plugin>
      <param name="can">can0</param>
      <param name="arm_prefix"></param>
    </hardware>
    <joint name="v10_joint1">
      <command_interface name="position"/>
      <command_interface name="velocity"/>
      <command_interface name="effort"/>
      <!-- State Interfaces -->
      <state_interface name="position">
        <param name="initial_value">0.0</param>
      </state_interface>
      <state_interface name="velocity">
        <param name="initial_value">0.0</param>
      </state_interface>
      <state_interface name="effort">
        <param name="initial_value">0.0</param>
      </state_interface>
    </joint>
    <joint name="v10_joint2">
      <command_interface name="position"/>
      <command_interface name="velocity"/>
      <command_interface name="effort"/>
      <!-- State Interfaces -->
      <state_interface name="position">
        <param name="initial_value">0.0</param>
      </state_interface>
      <state_interface name="velocity">
        <param name="initial_value">0.0</param>
      </state_interface>
      <state_interface name="effort">
        <param name="initial_value">0.0</param>
      </state_interface>
    </joint>
    <joint name="v10_joint3">
      <command_interface name="position"/>
      <command_interface name="velocity"/>
      <command_interface name="effort"/>
      <!-- State Interfaces -->
      <state_interface name="position">
        <param name="initial_value">0.0</param>
      </state_interface>
      <state_interface name="velocity">
        <param name="initial_value">0.0</param>
      </state_interface>
      <state_interface name="effort">
        <param name="initial_value">0.0</param>
      </state_interface>
    </joint>
    <joint name="v10_joint4">
      <command_interface name="position"/>
      <command_interface name="velocity"/>
      <command_interface name="effort"/>
      <!-- State Interfaces -->
      <state_interface name="position">
        <param name="initial_value">0.0</param>
      </state_interface>
      <state_interface name="velocity">
        <param name="initial_value">0.0</param>
      </state_interface>
      <state_interface name="effort">
        <param name="initial_value">0.0</param>
      </state_interface>
    </joint>
    <joint name="v10_joint5">
      <command_interface name="position"/>
      <command_interface name="velocity"/>
      <command_interface name="effort"/>
      <!-- State Interfaces -->
      <state_interface name="position">
        <param name="initial_value">0.0</param>
      </state_interface>
      <state_interface name="velocity">
        <param name="initial_value">0.0</param>
      </state_interface>
      <state_interface name="effort">
        <param name="initial_value">0.0</param>
      </state_interface>
    </joint>
    <joint name="v10_joint6">
      <command_interface name="position"/>
      <command_interface name="velocity"/>
      <command_interface name="effort"/>
      <!-- State Interfaces -->
      <state_interface name="position">
        <param name="initial_value">0.0</param>
      </state_interface>
      <state_interface name="velocity">
        <param name="initial_value">0.0</param>
      </state_interface>
      <state_interface name="effort">
        <param name="initial_value">0.0</param>
      </state_interface>
    </joint>
    <joint name="v10_joint7">
      <command_interface name="position"/>
      <command_interface name="velocity"/>
      <command_interface name="effort"/>
      <!-- State Interfaces -->
      <state_interface name="position">
        <param name="initial_value">0.0</param>
      </state_interface>
      <state_interface name="velocity">
        <param name="initial_value">0.0</param>
      </state_interface>
      <state_interface name="effort">
        <param name="initial_value">0.0</param>
      </state_interface>
    </joint>
  </ros2_control>
  <!-- <joint name="${ee_prefix}hand_joint" type="fixed"> -->
  <joint name="openarm_hand_joint" type="fixed">
    <parent link="openarm_link8"/>
    <child link="openarm_hand"/>
    <origin rpy="0 0 0" xyz="0 0 0"/>
  </joint>
  <!-- <xacro:ee_link_with_sc name="hand" gazebo="${gazebo}" prefix="${ee_prefix}" ee_kinematics_link="${ee_kinematics_link}"/> -->
  <link name="openarm_hand"/>
  <!-- Define the hand_tcp frame -->
  <link name="openarm_hand_tcp"/>
  <joint name="openarm_hand_tcp_joint" type="fixed">
    <!-- <origin xyz="0 0.1 0.06" rpy="${tcp_rpy}" /> -->
    <origin rpy="0 0 0" xyz="0 0 0.0"/>
    <parent link="openarm_hand"/>
    <child link="openarm_hand_tcp"/>
  </joint>
  <link name="openarm_left_finger">
    <visual name="openarm_left_finger_visual">
      <origin rpy="0.0 0.0 0.0" xyz="0.0 -0.05 -0.673001"/>
      <geometry>
        <mesh filename="package://openarm_description/meshes/ee/openarm_hand/visual/finger.dae" scale="0.001 0.001 0.001"/>
      </geometry>
    </visual>
    <collision name="openarm_left_finger_collision">
      <origin rpy="0.0 0.0 0.0" xyz="0.0 -0.05 -0.673001"/>
      <geometry>
        <mesh filename="package://openarm_description/meshes/ee/openarm_hand/collision/finger.stl" scale="0.001 0.001 0.001"/>
      </geometry>
    </collision>
  </link>
  <link name="openarm_right_finger">
    <visual name="openarm_right_finger_visual">
      <origin rpy="0.0 0.0 0.0" xyz="0.0 0.05 -0.673001"/>
      <geometry>
        <mesh filename="package://openarm_description/meshes/ee/openarm_hand/visual/finger.dae" scale="0.001 -0.001 0.001"/>
      </geometry>
    </visual>
    <collision name="openarm_right_finger_collision">
      <origin rpy="0.0 0.0 0.0" xyz="0.0 -0.05 -0.673001"/>
      <geometry>
        <mesh filename="package://openarm_description/meshes/ee/openarm_hand/collision/finger.stl" scale="0.001 -0.001 0.001"/>
      </geometry>
    </collision>
  </link>
  <!-- <joint name="${ee_prefix}finger_joint1" type="prismatic">
      <parent link="${ee_prefix}hand" />
      <child link="${ee_prefix}right_finger" />
      <origin xyz="0 0.05 0" rpy="0 0 0" />
      <axis xyz="0 -1 0" />
      <limit effort="100" lower="0.0" upper="0.044" velocity="0.2" />
    </joint>

    <joint name="${ee_prefix}finger_joint2" type="prismatic">
      <parent link="${ee_prefix}hand" />
      <child link="${ee_prefix}left_finger" />
      <origin xyz="0 0.15 0" rpy="0 0 0" />
      <axis xyz="0 1 0" />
      <limit effort="100" lower="0.0" upper="0.044" velocity="0.2" />
      <mimic joint="${ee_prefix}finger_joint1" />
    </joint> -->
  <joint name="openarm_finger_joint1" type="prismatic">
    <parent link="openarm_hand"/>
    <child link="openarm_right_finger"/>
    <origin rpy="0 0 0" xyz="0 0.095 0"/>
    <axis xyz="0 -1 0"/>
    <limit effort="100" lower="0.0" upper="0.044" velocity="0.2"/>
  </joint>
  <joint name="openarm_finger_joint2" type="prismatic">
    <parent link="openarm_hand"/>
    <child link="openarm_left_finger"/>
    <origin rpy="0 0 0" xyz="0 0.105 0"/>
    <axis xyz="0 1 0"/>
    <limit effort="100" lower="0.0" upper="0.044" velocity="0.2"/>
    <mimic joint="openarm_finger_joint1"/>
  </joint>
  <!-- <xacro:if value="${hand and ee_type != 'none' and ee_type != 'openarm_hand'}">
        <xacro:property name="special_connection" value="$(arg special_connection)" />
        <xacro:property name="connection" value="${special_connection if special_connection == '' else arm_type + '_link8'}" />
        <xacro:ee_with_one_link
            connected_to="${arm_prefix_modified}${connection}"
            arm_type="${arm_type}"
            arm_prefix="${arm_prefix_modified}"
            ee_type="${ee_type}"
            ee_inertials="${xacro.load_yaml('$(find openarm_description)/config/hand/$(arg ee_type)_inertials.yaml')}"
            ee_kinematics_link="${xacro.load_yaml('$(find openarm_description)/config/hand/openarm_hand/kinematics_link.yaml')}"
            rpy_ee="$(arg rpy_ee)"
            xyz_ee="$(arg xyz_ee)"
            tcp_xyz="$(arg tcp_xyz)"
            tcp_rpy="$(arg tcp_rpy)"
            gazebo="${gazebo}"
            description_pkg="$(arg description_pkg)"
        />
        </xacro:if> -->
  <!-- <xacro:if value="${gazebo}">
        <xacro:if value="${parent != ''}">
            <xacro:if value="${parent == 'world'}">
            <link name="${parent}" />
            </xacro:if>
            <joint name="${parent}_joint" type="fixed">
            <origin xyz="${xyz}" rpy="${rpy}" />
            <parent link="${parent}" />
            <child  link="${arm_type}_link0" />
            </joint>
        </xacro:if> -->
  <!-- <xacro:gazebo-joint joint="${arm_type}_joint1" transmission="hardware_interface/PositionJointInterface" />
        <xacro:gazebo-joint joint="${arm_type}_joint2" transmission="hardware_interface/PositionJointInterface" />
        <xacro:gazebo-joint joint="${arm_type}_joint3" transmission="hardware_interface/PositionJointInterface" />
        <xacro:gazebo-joint joint="${arm_type}_joint4" transmission="hardware_interface/PositionJointInterface" />
        <xacro:gazebo-joint joint="${arm_type}_joint5" transmission="hardware_interface/PositionJointInterface" />
        <xacro:gazebo-joint joint="${arm_type}_joint6" transmission="hardware_interface/PositionJointInterface" />
        <xacro:gazebo-joint joint="${arm_type}_joint7" transmission="hardware_interface/PositionJointInterface" />

        <xacro:gazebo-joint joint="${arm_type}_joint1" transmission="hardware_interface/VelocityJointInterface" />
        <xacro:gazebo-joint joint="${arm_type}_joint2" transmission="hardware_interface/VelocityJointInterface" />
        <xacro:gazebo-joint joint="${arm_type}_joint3" transmission="hardware_interface/VelocityJointInterface" />
        <xacro:gazebo-joint joint="${arm_type}_joint4" transmission="hardware_interface/VelocityJointInterface" />
        <xacro:gazebo-joint joint="${arm_type}_joint5" transmission="hardware_interface/VelocityJointInterface" />
        <xacro:gazebo-joint joint="${arm_type}_joint6" transmission="hardware_interface/VelocityJointInterface" />
        <xacro:gazebo-joint joint="${arm_type}_joint7" transmission="hardware_interface/VelocityJointInterface" />

        <xacro:gazebo-joint joint="${arm_type}_joint1" transmission="hardware_interface/EffortJointInterface" />
        <xacro:gazebo-joint joint="${arm_type}_joint2" transmission="hardware_interface/EffortJointInterface" />
        <xacro:gazebo-joint joint="${arm_type}_joint3" transmission="hardware_interface/EffortJointInterface" />
        <xacro:gazebo-joint joint="${arm_type}_joint4" transmission="hardware_interface/EffortJointInterface" />
        <xacro:gazebo-joint joint="${arm_type}_joint5" transmission="hardware_interface/EffortJointInterface" />
        <xacro:gazebo-joint joint="${arm_type}_joint6" transmission="hardware_interface/EffortJointInterface" />
        <xacro:gazebo-joint joint="${arm_type}_joint7" transmission="hardware_interface/EffortJointInterface" />  -->
  <!-- <xacro:transmission-openarm-state arm_type="${arm_type}" />
        <xacro:transmission-openarm-model arm_type="${arm_type}"
            root="${arm_type}_joint1"
            tip="${arm_type}_joint8"
        /> -->
  <!-- <xacro:if value="${ee_type == 'openarm_hand'}">
            <xacro:gazebo-joint joint="${arm_type}_finger_joint1" transmission="hardware_interface/EffortJointInterface" />
            <xacro:gazebo-joint joint="${arm_type}_finger_joint2" transmission="hardware_interface/EffortJointInterface" />
            <xacro:gazebo-friction link="${arm_type}_leftfinger" mu="1.13" />
            <xacro:gazebo-friction link="${arm_type}_rightfinger" mu="1.13" />
        </xacro:if>
        </xacro:if> -->
</robot>
